Workbook

Sheet Overall
A1: compound | B1: MOA | C1: num_concordant | D1: num_discordant | E1: ratio | F1: RMGI | G1: EFO27 | H1: RMUGS | I1: HA1E | J1: SNGM | K1: HEPG2 | L1: NPC | M1: SKB | N1: VCAP | O1: SKLU1 | P1: COV644 | Q1: HEC108 | R1: MCF7 | S1: A375 | T1: HCC515 | U1: MDAMB231 | V1: LNCAP | W1: BT20 | X1: MCF10A | Y1: HME1 | Z1: ASC | AA1: SKBR3 | AB1: HT29 | AC1: PC3 | AD1: HS578T | AE1: SW620 | AF1: SW480 | AG1: CORL23 | AH1: OV7 | AI1: THP1 | AJ1: A549 | AK1: HCT116 | AL1: LOVO | AM1: CD34 | AN1: NOMO1 | AO1: PHH | AP1: NPC.TAK | AQ1: HUVEC | AR1: HEK293T | AS1: RKO | AT1: PL21 | AU1: ASC.C | AV1: SKL | AW1: HELA | AX1: SW948 | AY1: SNU1040 | AZ1: TYKNU | BA1: NCIH1694 | BB1: AGS | BC1: HUH7 | BD1: DV90 | BE1: SKMEL1 | BF1: U937 | BG1: T3M10 | BH1: YAPC | BI1: NCIH2073 | BJ1: MDST8 | BK1: NKDBA | BL1: NEU | BM1: HL60 | BN1: SNUC4 | BO1: U266 | BP1: HUES3 | BQ1: SKL.C | BR1: HCC15 | BS1: A673 | BT1: WSUDLCL2 | BU1: SNUC5 | BV1: SKMEL28 | BW1: NCIH1836 | BX1: NPC.CAS9 | BY1: H1299 | BZ1: JHUEM2 | CA1: FIBRNPC | CB1: NCIH508 | CC1: NCIH596 | CD1: SKM1 | CE1: MNEU.E | CF1: JURKAT | CG1: HT115 | CH1: CL34 | CI1: HS27A
A2: Ursolic acid | B2: =VLOOKUP(A2,MOA!$C$2:$D$1253,2,FALSE) -> 11-beta hydroxysteroid dehydrogenase inhibitor|Acetylcholinesterase inhibitor|Caspase inhibitor|HIV protease inhibitor|Lipid peroxidase inhibitor|Quorum sensing signaling modulator|Steryl sulfatase inhibitor|Tyrosine phosphatase inhibitor|ATPase inhibitor|NFkB pathway inhibitor|STAT inhibitor | C2: 2 | D2: 4 | E2: 0.5 | F2: NA | G2: NA | H2: NA | I2: NA | J2: NA | K2: NA | L2: NA | M2: NA | N2: NA | O2: NA | P2: NA | Q2: NA | R2: -0.41715174 | S2: 0.37514809 | T2: NA | U2: NA | V2: NA | W2: NA | X2: NA | Y2: NA | Z2: NA | AA2: NA | AB2: NA | AC2: NA | AD2: NA | AE2: NA | AF2: NA | AG2: NA | AH2: NA | AI2: NA | AJ2: NA | AK2: NA | AL2: NA | AM2: NA | AN2: NA | AO2: NA | AP2: NA | AQ2: NA | AR2: NA | AS2: NA | AT2: -0.38896279 | AU2: NA | AV2: NA | AW2: NA | AX2: NA | AY2: NA | AZ2: NA | BA2: NA | BB2: NA | BC2: NA | BD2: NA | BE2: NA | BF2: NA | BG2: NA | BH2: -0.44153866 | BI2: NA | BJ2: NA | BK2: NA | BL2: NA | BM2: NA | BN2: NA | BO2: NA | BP2: NA | BQ2: NA | BR2: -0.59017186 | BS2: NA | BT2: NA | BU2: NA | BV2: NA | BW2: NA | BX2: NA | BY2: 0.39281064 | BZ2: NA | CA2: NA | CB2: NA | CC2: NA | CD2: NA | CE2: NA | CF2: NA | CG2: NA | CH2: NA | CI2: NA
A3: Chenodiol | B3: =VLOOKUP(A3,MOA!$C$2:$D$1253,2,FALSE) -> 11-beta-HSD1 inhibitor|FXR agonist | C3: 2 | D3: 1 | E3: 2 | F3: NA | G3: NA | H3: NA | I3: NA | J3: NA | K3: NA | L3: NA | M3: NA | N3: 0.40903044 | O3: NA | P3: NA | Q3: NA | R3: NA | S3: NA | T3: NA | U3: NA | V3: NA | W3: NA | X3: NA | Y3: NA | Z3: NA | AA3: NA | AB3: NA | AC3: NA | AD3: NA | AE3: NA | AF3: NA | AG3: NA | AH3: NA | AI3: NA | AJ3: 0.46323529 | AK3: NA | AL3: NA | AM3: NA | AN3: NA | AO3: NA | AP3: NA | AQ3: NA | AR3: NA | AS3: NA | AT3: NA | AU3: NA | AV3: NA | AW3: NA | AX3: NA | AY3: NA | AZ3: NA | BA3: NA | BB3: NA | BC3: NA | BD3: NA | BE3: NA | BF3: NA | BG3: NA | BH3: NA | BI3: NA | BJ3: NA | BK3: NA | BL3: -0.41197575 | BM3: NA | BN3: NA | BO3: NA | BP3: NA | BQ3: NA | BR3: NA | BS3: NA | BT3: NA | BU3: NA | BV3: NA | BW3: NA | BX3: NA | BY3: NA | BZ3: NA | CA3: NA | CB3: NA | CC3: NA | CD3: NA | CE3: NA | CF3: NA | CG3: NA | CH3: NA | CI3: NA
A4: Dolasetron | B4: =IFERROR(VLOOKUP(A4, [1]Overall!$A$2:$B$1442, 2, FALSE), IFERROR(VLOOKUP(A4, [1]Female!$A$2:$B$1276, 2, FALSE), IFERROR(VLOOKUP(A4, [1]Male!$A$2:$B$1529, 2, FALSE), "Not Found"))) -> 5-HT3 receptor antagonist | C4: 2 | D4: 1 | E4: 2 | F4: NA | G4: NA | H4: NA | I4: NA | J4: NA | K4: NA | L4: NA | M4: NA | N4: NA | O4: NA | P4: NA | Q4: NA | R4: NA | S4: NA | T4: NA | U4: NA | V4: NA | W4: NA | X4: NA | Y4: NA | Z4: NA | AA4: NA | AB4: NA | AC4: 0.52586095 | AD4: NA | AE4: NA | AF4: NA | AG4: NA | AH4: NA | AI4: NA | AJ4: NA | AK4: NA | AL4: NA | AM4: NA | AN4: NA | AO4: NA | AP4: NA | AQ4: NA | AR4: NA | AS4: NA | AT4: NA | AU4: NA | AV4: NA | AW4: 0.61162177 | AX4: NA | AY4: NA | AZ4: NA | BA4: NA | BB4: NA | BC4: NA | BD4: NA | BE4: NA | BF4: NA | BG4: NA | BH4: -0.38254244 | BI4: NA | BJ4: NA | BK4: NA | BL4: NA | BM4: NA | BN4: NA | BO4: NA | BP4: NA | BQ4: NA | BR4: NA | BS4: NA | BT4: NA | BU4: NA | BV4: NA | BW4: NA | BX4: NA | BY4: NA | BZ4: NA | CA4: NA | CB4: NA | CC4: NA | CD4: NA | CE4: NA | CF4: NA | CG4: NA | CH4: NA | CI4: NA
A5: Nilotinib | B5: =VLOOKUP(A5,MOA!$C$2:$D$1253,2,FALSE) -> Abl kinase inhibitor|Bcr-Abl kinase inhibitor | C5: 6 | D5: 4 | E5: 1.5 | F5: NA | G5: NA | H5: NA | I5: 0.60205356 | J5: NA | K5: 0.5930708 | L5: NA | M5: NA | N5: NA | O5: NA | P5: NA | Q5: NA | R5: 0.52009602 | S5: -0.43367323 | T5: 0.41538502 | U5: -0.53309512 | V5: NA | W5: 0.41931446 | X5: -0.40179761 | Y5: NA | Z5: NA | AA5: NA | AB5: 0.5704978 | AC5: NA | AD5: -0.45167339 | AE5: NA | AF5: NA | AG5: NA | AH5: NA | AI5: NA | AJ5: NA | AK5: NA | AL5: NA | AM5: NA | AN5: NA | AO5: NA | AP5: NA | AQ5: NA | AR5: NA | AS5: NA | AT5: NA | AU5: NA | AV5: NA | AW5: NA | AX5: NA | AY5: NA | AZ5: NA | BA5: NA | BB5: NA | BC5: NA | BD5: NA | BE5: NA | BF5: NA | BG5: NA | BH5: NA | BI5: NA | BJ5: NA | BK5: NA | BL5: NA | BM5: NA | BN5: NA | BO5: NA | BP5: NA | BQ5: NA | BR5: NA | BS5: NA | BT5: NA | BU5: NA | BV5: NA | BW5: NA | BX5: NA | BY5: NA | BZ5: NA | CA5: NA | CB5: NA | CC5: NA | CD5: NA | CE5: NA | CF5: NA | CG5: NA | CH5: NA | CI5: NA
A6: Bosutinib | B6: =VLOOKUP(A6,MOA!$C$2:$D$1253,2,FALSE) -> Abl kinase inhibitor|Bcr-Abl kinase inhibitor|Src inhibitor | C6: 9 | D6: 6 | E6: 1.5 | F6: NA | G6: NA | H6: NA | I6: 0.4585315 | J6: NA | K6: 0.34049906 | L6: NA | M6: NA | N6: 0.46719759 | O6: NA | P6: NA | Q6: NA | R6: 0.61069783 | S6: -0.34735482 | T6: -0.48763865 | U6: NA | V6: NA | W6: NA | X6: NA | Y6: NA | Z6: NA | AA6: NA | AB6: 0.65370649 | AC6: 0.61185156 | AD6: NA | AE6: NA | AF6: NA | AG6: NA | AH6: NA | AI6: NA | AJ6: NA | AK6: NA | AL6: NA | AM6: -0.49431266 | AN6: NA | AO6: NA | AP6: -0.39507729 | AQ6: -0.44253745 | AR6: NA | AS6: NA | AT6: NA | AU6: NA | AV6: NA | AW6: NA | AX6: NA | AY6: NA | AZ6: NA | BA6: NA | BB6: NA | BC6: NA | BD6: NA | BE6: NA | BF6: NA | BG6: NA | BH6: NA | BI6: NA | BJ6: NA | BK6: NA | BL6: 0.56784643 | BM6: NA | BN6: NA | BO6: NA | BP6: NA | BQ6: 0.46699363 | BR6: NA | BS6: NA | BT6: NA | BU6: NA | BV6: NA | BW6: NA | BX6: NA | BY6: NA | BZ6: NA | CA6: NA | CB6: NA | CC6: NA | CD6: NA | CE6: -0.45533879 | CF6: 0.41669696 | CG6: NA | CH6: NA | CI6: NA
A7: Avasimibe | B7: =IFERROR(VLOOKUP(A7, [1]Overall!$A$2:$B$1442, 2, FALSE), IFERROR(VLOOKUP(A7, [1]Female!$A$2:$B$1276, 2, FALSE), IFERROR(VLOOKUP(A7, [1]Male!$A$2:$B$1529, 2, FALSE), "Not Found"))) -> ACAT inhibitor, lowers cholesterol | C7: 0 | D7: 4 | E7: 0 | F7: NA | G7: NA | H7: NA | I7: NA | J7: NA | K7: NA | L7: NA | M7: NA | N7: NA | O7: NA | P7: NA | Q7: NA | R7: NA | S7: NA | T7: NA | U7: NA | V7: NA | W7: NA | X7: NA | Y7: NA | Z7: NA | AA7: NA | AB7: -0.42452364 | AC7: -0.46861314 | AD7: NA | AE7: NA | AF7: NA | AG7: NA | AH7: NA | AI7: NA | AJ7: NA | AK7: NA | AL7: NA | AM7: NA | AN7: NA | AO7: NA | AP7: NA | AQ7: NA | AR7: NA | AS7: NA | AT7: NA | AU7: NA | AV7: NA | AW7: -0.57097632 | AX7: NA | AY7: NA | AZ7: NA | BA7: NA | BB7: NA | BC7: NA | BD7: NA | BE7: NA | BF7: NA | BG7: NA | BH7: -0.47669182 | BI7: NA | BJ7: NA | BK7: NA | BL7: NA | BM7: NA | BN7: NA | BO7: NA | BP7: NA | BQ7: NA | BR7: NA | BS7: NA | BT7: NA | BU7: NA | BV7: NA | BW7: NA | BX7: NA | BY7: NA | BZ7: NA | CA7: NA | CB7: NA | CC7: NA | CD7: NA | CE7: NA | CF7: NA | CG7: NA | CH7: NA | CI7: NA
A8: TOFA | B8: =IFERROR(VLOOKUP(A8, [1]Overall!$A$2:$B$1442, 2, FALSE), IFERROR(VLOOKUP(A8, [1]Female!$A$2:$B$1276, 2, FALSE), IFERROR(VLOOKUP(A8, [1]Male!$A$2:$B$1529, 2, FALSE), "Not Found"))) -> Acetyl-CoA carboxylase inhibitor | C8: 1 | D8: 1 | E8: 1 | F8: NA | G8: NA | H8: NA | I8: 0.47320575 | J8: NA | K8: NA | L8: NA | M8: NA | N8: NA | O8: NA | P8: NA | Q8: NA | R8: -0.51459462 | S8: NA | T8: NA | U8: NA | V8: NA | W8: NA | X8: NA | Y8: NA | Z8: NA | AA8: NA | AB8: NA | AC8: NA | AD8: NA | AE8: NA | AF8: NA | AG8: NA | AH8: NA | AI8: NA | AJ8: NA | AK8: NA | AL8: NA | AM8: NA | AN8: NA | AO8: NA | AP8: NA | AQ8: NA | AR8: NA | AS8: NA | AT8: NA | AU8: NA | AV8: NA | AW8: NA | AX8: NA | AY8: NA | AZ8: NA | BA8: NA | BB8: NA | BC8: NA | BD8: NA | BE8: NA | BF8: NA | BG8: NA | BH8: NA | BI8: NA | BJ8: NA | BK8: NA | BL8: NA | BM8: NA | BN8: NA | BO8: NA | BP8: NA | BQ8: NA | BR8: NA | BS8: NA | BT8: NA | BU8: NA | BV8: NA | BW8: NA | BX8: NA | BY8: NA | BZ8: NA | CA8: NA | CB8: NA | CC8: NA | CD8: NA | CE8: NA | CF8: NA | CG8: NA | CH8: NA | CI8: NA
A9: Nicotine | B9: =VLOOKUP(A9,MOA!$C$2:$D$1253,2,FALSE) -> Acetylcholine receptor agonist | C9: 1 | D9: 2 | E9: 0.5 | F9: NA | G9: NA | H9: NA | I9: NA | J9: NA | K9: NA | L9: NA | M9: NA | N9: NA | O9: NA | P9: NA | Q9: NA | R9: NA | S9: NA | T9: 0.53796694 | U9: NA | V9: NA | W9: NA | X9: NA | Y9: NA | Z9: NA | AA9: NA | AB9: NA | AC9: -0.44114869 | AD9: NA | AE9: NA | AF9: NA | AG9: NA | AH9: NA | AI9: NA | AJ9: NA | AK9: NA | AL9: NA | AM9: NA | AN9: NA | AO9: NA | AP9: NA | AQ9: NA | AR9: NA | AS9: NA | AT9: NA | AU9: NA | AV9: NA | AW9: -0.46344734 | AX9: NA | AY9: NA | AZ9: NA | BA9: NA | BB9: NA | BC9: NA | BD9: NA | BE9: NA | BF9: NA | BG9: NA | BH9: NA | BI9: NA | BJ9: NA | BK9: NA | BL9: NA | BM9: NA | BN9: NA | BO9: NA | BP9: NA | BQ9: NA | BR9: NA | BS9: NA | BT9: NA | BU9: NA | BV9: NA | BW9: NA | BX9: NA | BY9: NA | BZ9: NA | CA9: NA | CB9: NA | CC9: NA | CD9: NA | CE9: NA | CF9: NA | CG9: NA | CH9: NA | CI9: NA
A10: Diphenidol | B10: =VLOOKUP(A10,MOA!$C$2:$D$1253,2,FALSE) -> Acetylcholine receptor agonist | C10: 1 | D10: 2 | E10: 0.5 | F10: NA | G10: NA | H10: NA | I10: -0.4378605 | J10: NA | K10: NA | L10: NA | M10: NA | N10: NA | O10: NA | P10: NA | Q10: NA | R10: NA | S10: NA | T10: NA | U10: NA | V10: NA | W10: NA | X10: NA | Y10: NA | Z10: NA | AA10: NA | AB10: NA | AC10: 0.39709324 | AD10: NA | AE10: NA | AF10: NA | AG10: NA | AH10: NA | AI10: NA | AJ10: NA | AK10: NA | AL10: NA | AM10: NA | AN10: NA | AO10: NA | AP10: NA | AQ10: NA | AR10: NA | AS10: NA | AT10: NA | AU10: NA | AV10: NA | AW10: NA | AX10: NA | AY10: NA | AZ10: NA | BA10: NA | BB10: NA | BC10: NA | BD10: NA | BE10: NA | BF10: NA | BG10: NA | BH10: -0.45739409 | BI10: NA | BJ10: NA | BK10: NA | BL10: NA | BM10: NA | BN10: NA | BO10: NA | BP10: NA | BQ10: NA | BR10: NA | BS10: NA | BT10: NA | BU10: NA | BV10: NA | BW10: NA | BX10: NA | BY10: NA | BZ10: NA | CA10: NA | CB10: NA | CC10: NA | CD10: NA | CE10: NA | CF10: NA | CG10: NA | CH10: NA | CI10: NA
A11: Piracetam | B11: =VLOOKUP(A11,MOA!$C$2:$D$1253,2,FALSE) -> Acetylcholine receptor agonist | C11: 2 | D11: 1 | E11: 2 | F11: NA | G11: NA | H11: NA | I11: NA | J11: NA | K11: NA | L11: NA | M11: NA | N11: NA | O11: NA | P11: NA | Q11: NA | R11: NA | S11: 0.4370581 | T11: NA | U11: NA | V11: NA | W11: NA | X11: NA | Y11: NA | Z11: NA | AA11: NA | AB11: NA | AC11: -0.41511177 | AD11: NA | AE11: NA | AF11: NA | AG11: NA | AH11: NA | AI11: NA | AJ11: NA | AK11: NA | AL11: NA | AM11: NA | AN11: NA | AO11: NA | AP11: NA | AQ11: NA | AR11: NA | AS11: NA | AT11: NA | AU11: NA | AV11: NA | AW11: 0.48561776 | AX11: NA | AY11: NA | AZ11: NA | BA11: NA | BB11: NA | BC11: NA | BD11: NA | BE11: NA | BF11: NA | BG11: NA | BH11: NA | BI11: NA | BJ11: NA | BK11: NA | BL11: NA | BM11: NA | BN11: NA | BO11: NA | BP11: NA | BQ11: NA | BR11: NA | BS11: NA | BT11: NA | BU11: NA | BV11: NA | BW11: NA | BX11: NA | BY11: NA | BZ11: NA | CA11: NA | CB11: NA | CC11: NA | CD11: NA | CE11: NA | CF11: NA | CG11: NA | CH11: NA | CI11: NA
A12: (R)-3-(piperidin-2-Yl)pyridine | B12: =VLOOKUP(A12,MOA!$C$2:$D$1253,2,FALSE) -> Acetylcholine receptor agonist | C12: 1 | D12: 1 | E12: 1 | F12: NA | G12: NA | H12: NA | I12: NA | J12: NA | K12: NA | L12: -0.35636956 | M12: NA | N12: NA | O12: NA | P12: NA | Q12: NA | R12: 0.46560788 | S12: NA | T12: NA | U12: NA | V12: NA | W12: NA | X12: NA | Y12: NA | Z12: NA | AA12: NA | AB12: NA | AC12: NA | AD12: NA | AE12: NA | AF12: NA | AG12: NA | AH12: NA | AI12: NA | AJ12: NA | AK12: NA | AL12: NA | AM12: NA | AN12: NA | AO12: NA | AP12: NA | AQ12: NA | AR12: NA | AS12: NA | AT12: NA | AU12: NA | AV12: NA | AW12: NA | AX12: NA | AY12: NA | AZ12: NA | BA12: NA | BB12: NA | BC12: NA | BD12: NA | BE12: NA | BF12: NA | BG12: NA | BH12: NA | BI12: NA | BJ12: NA | BK12: NA | BL12: NA | BM12: NA | BN12: NA | BO12: NA | BP12: NA | BQ12: NA | BR12: NA | BS12: NA | BT12: NA | BU12: NA | BV12: NA | BW12: NA | BX12: NA | BY12: NA | BZ12: NA | CA12: NA | CB12: NA | CC12: NA | CD12: NA | CE12: NA | CF12: NA | CG12: NA | CH12: NA | CI12: NA
A13: Pilocarpine | B13: =VLOOKUP(A13,MOA!$C$2:$D$1253,2,FALSE) -> Acetylcholine receptor agonist | C13: 1 | D13: 1 | E13: 1 | F13: NA | G13: NA | H13: NA | I13: 0.50391568 | J13: NA | K13: NA | L13: NA | M13: NA | N13: NA | O13: NA | P13: NA | Q13: NA | R13: NA | S13: NA | T13: NA | U13: NA | V13: NA | W13: NA | X13: NA | Y13: NA | Z13: NA | AA13: NA | AB13: NA | AC13: -0.51131982 | AD13: NA | AE13: NA | AF13: NA | AG13: NA | AH13: NA | AI13: NA | AJ13: NA | AK13: NA | AL13: NA | AM13: NA | AN13: NA | AO13: NA | AP13: NA | AQ13: NA | AR13: NA | AS13: NA | AT13: NA | AU13: NA | AV13: NA | AW13: NA | AX13: NA | AY13: NA | AZ13: NA | BA13: NA | BB13: NA | BC13: NA | BD13: NA | BE13: NA | BF13: NA | BG13: NA | BH13: NA | BI13: NA | BJ13: NA | BK13: NA | BL13: NA | BM13: NA | BN13: NA | BO13: NA | BP13: NA | BQ13: NA | BR13: NA | BS13: NA | BT13: NA | BU13: NA | BV13: NA | BW13: NA | BX13: NA | BY13: NA | BZ13: NA | CA13: NA | CB13: NA | CC13: NA | CD13: NA | CE13: NA | CF13: NA | CG13: NA | CH13: NA | CI13: NA
A14: Tremorine | B14: =VLOOKUP(A14,MOA!$C$2:$D$1253,2,FALSE) -> Acetylcholine receptor agonist | C14: 1 | D14: 1 | E14: 1 | F14: NA | G14: NA | H14: NA | I14: NA | J14: NA | K14: NA | L14: NA | M14: NA | N14: NA | O14: NA | P14: NA | Q14: NA | R14: -0.48969121 | S14: NA | T14: NA | U14: NA | V14: NA | W14: NA | X14: NA | Y14: NA | Z14: NA | AA14: NA | AB14: NA | AC14: 0.38637211 | AD14: NA | AE14: NA | AF14: NA | AG14: NA | AH14: NA | AI14: NA | AJ14: NA | AK14: NA | AL14: NA | AM14: NA | AN14: NA | AO14: NA | AP14: NA | AQ14: NA | AR14: NA | AS14: NA | AT14: NA | AU14: NA | AV14: NA | AW14: NA | AX14: NA | AY14: NA | AZ14: NA | BA14: NA | BB14: NA | BC14: NA | BD14: NA | BE14: NA | BF14: NA | BG14: NA | BH14: NA | BI14: NA | BJ14: NA | BK14: NA | BL14: NA | BM14: NA | BN14: NA | BO14: NA | BP14: NA | BQ14: NA | BR14: NA | BS14: NA | BT14: NA | BU14: NA | BV14: NA | BW14: NA | BX14: NA | BY14: NA | BZ14: NA | CA14: NA | CB14: NA | CC14: NA | CD14: NA | CE14: NA | CF14: NA | CG14: NA | CH14: NA | CI14: NA
A15: Adapiprazine | B15: =VLOOKUP(A15,MOA!$C$2:$D$1253,2,FALSE) -> Acetylcholine receptor agonist | C15: 2 | D15: 0 | E15: Inf | F15: NA | G15: NA | H15: NA | I15: NA | J15: NA | K15: NA | L15: 0.41512195 | M15: NA | N15: NA | O15: NA | P15: NA | Q15: NA | R15: NA | S15: NA | T15: NA | U15: NA | V15: NA | W15: NA | X15: NA | Y15: NA | Z15: NA | AA15: NA | AB15: NA | AC15: NA | AD15: NA | AE15: NA | AF15: NA | AG15: NA | AH15: NA | AI15: NA | AJ15: NA | AK15: NA | AL15: NA | AM15: NA | AN15: NA | AO15: NA | AP15: NA | AQ15: NA | AR15: NA | AS15: NA | AT15: NA | AU15: NA | AV15: NA | AW15: NA | AX15: NA | AY15: NA | AZ15: NA | BA15: NA | BB15: NA | BC15: NA | BD15: NA | BE15: NA | BF15: NA | BG15: NA | BH15: NA | BI15: NA | BJ15: NA | BK15: NA | BL15: 0.48039733 | BM15: NA | BN15: NA | BO15: NA | BP15: NA | BQ15: NA | BR15: NA | BS15: NA | BT15: NA | BU15: NA | BV15: NA | BW15: NA | BX15: NA | BY15: NA | BZ15: NA | CA15: NA | CB15: NA | CC15: NA | CD15: NA | CE15: NA | CF15: NA | CG15: NA | CH15: NA | CI15: NA
A16: N-Methyltropan-3-yl 2-(4-bromophenyl)propionate | B16: =VLOOKUP(A16,MOA!$C$2:$D$1253,2,FALSE) -> Acetylcholine receptor agonist | C16: 2 | D16: 0 | E16: Inf | F16: NA | G16: NA | H16: NA | I16: NA | J16: NA | K16: NA | L16: NA | M16: NA | N16: NA | O16: NA | P16: NA | Q16: NA | R16: NA | S16: NA | T16: 0.52471735 | U16: NA | V16: NA | W16: NA | X16: NA | Y16: NA | Z16: NA | AA16: NA | AB16: 0.55085817 | AC16: NA | AD16: NA | AE16: NA | AF16: NA | AG16: NA | AH16: NA | AI16: NA | AJ16: NA | AK16: NA | AL16: NA | AM16: NA | AN16: NA | AO16: NA | AP16: NA | AQ16: NA | AR16: NA | AS16: NA | AT16: NA | AU16: NA | AV16: NA | AW16: NA | AX16: NA | AY16: NA | AZ16: NA | BA16: NA | BB16: NA | BC16: NA | BD16: NA | BE16: NA | BF16: NA | BG16: NA | BH16: NA | BI16: NA | BJ16: NA | BK16: NA | BL16: NA | BM16: NA | BN16: NA | BO16: NA | BP16: NA | BQ16: NA | BR16: NA | BS16: NA | BT16: NA | BU16: NA | BV16: NA | BW16: NA | BX16: NA | BY16: NA | BZ16: NA | CA16: NA | CB16: NA | CC16: NA | CD16: NA | CE16: NA | CF16: NA | CG16: NA | CH16: NA | CI16: NA
A17: Arecaidine but-2-ynyl ester | B17: =VLOOKUP(A17,MOA!$C$2:$D$1253,2,FALSE) -> Acetylcholine receptor agonist | C17: 2 | D17: 0 | E17: Inf | F17: NA | G17: NA | H17: NA | I17: NA | J17: NA | K17: NA | L17: NA | M17: 0.41387658 | N17: NA | O17: NA | P17: NA | Q17: NA | R17: 0.54851785 | S17: NA | T17: NA | U17: NA | V17: NA | W17: NA | X17: NA | Y17: NA | Z17: NA | AA17: NA | AB17: NA | AC17: NA | AD17: NA | AE17: NA | AF17: NA | AG17: NA | AH17: NA | AI17: NA | AJ17: NA | AK17: NA | AL17: NA | AM17: NA | AN17: NA | AO17: NA | AP17: NA | AQ17: NA | AR17: NA | AS17: NA | AT17: NA | AU17: NA | AV17: NA | AW17: NA | AX17: NA | AY17: NA | AZ17: NA | BA17: NA | BB17: NA | BC17: NA | BD17: NA | BE17: NA | BF17: NA | BG17: NA | BH17: NA | BI17: NA | BJ17: NA | BK17: NA | BL17: NA | BM17: NA | BN17: NA | BO17: NA | BP17: NA | BQ17: NA | BR17: NA | BS17: NA | BT17: NA | BU17: NA | BV17: NA | BW17: NA | BX17: NA | BY17: NA | BZ17: NA | CA17: NA | CB17: NA | CC17: NA | CD17: NA | CE17: NA | CF17: NA | CG17: NA | CH17: NA | CI17: NA
A18: Arecaidine Propargyl Ester | B18: =VLOOKUP(A18,MOA!$C$2:$D$1253,2,FALSE) -> Acetylcholine receptor agonist | C18: 3 | D18: 0 | E18: Inf | F18: NA | G18: NA | H18: NA | I18: NA | J18: NA | K18: NA | L18: 0.4543325 | M18: NA | N18: NA | O18: NA | P18: NA | Q18: NA | R18: NA | S18: 0.49262576 | T18: NA | U18: NA | V18: NA | W18: NA | X18: NA | Y18: NA | Z18: NA | AA18: NA | AB18: NA | AC18: NA | AD18: NA | AE18: NA | AF18: NA | AG18: NA | AH18: NA | AI18: NA | AJ18: 0.49852597 | AK18: NA | AL18: NA | AM18: NA | AN18: NA | AO18: NA | AP18: NA | AQ18: NA | AR18: NA | AS18: NA | AT18: NA | AU18: NA | AV18: NA | AW18: NA | AX18: NA | AY18: NA | AZ18: NA | BA18: NA | BB18: NA | BC18: NA | BD18: NA | BE18: NA | BF18: NA | BG18: NA | BH18: NA | BI18: NA | BJ18: NA | BK18: NA | BL18: NA | BM18: NA | BN18: NA | BO18: NA | BP18: NA | BQ18: NA | BR18: NA | BS18: NA | BT18: NA | BU18: NA | BV18: NA | BW18: NA | BX18: NA | BY18: NA | BZ18: NA | CA18: NA | CB18: NA | CC18: NA | CD18: NA | CE18: NA | CF18: NA | CG18: NA | CH18: NA | CI18: NA
A19: Mepenzolate | B19: =VLOOKUP(A19,MOA!$C$2:$D$1253,2,FALSE) -> Acetylcholine receptor antagonist | C19: 1 | D19: 1 | E19: 1 | F19: NA | G19: NA | H19: NA | I19: NA | J19: NA | K19: NA | L19: NA | M19: NA | N19: NA | O19: NA | P19: NA | Q19: NA | R19: -0.41740508 | S19: NA | T19: NA | U19: NA | V19: NA | W19: NA | X19: NA | Y19: NA | Z19: NA | AA19: NA | AB19: NA | AC19: 0.37456025 | AD19: NA | AE19: NA | AF19: NA | AG19: NA | AH19: NA | AI19: NA | AJ19: NA | AK19: NA | AL19: NA | AM19: NA | AN19: NA | AO19: NA | AP19: NA | AQ19: NA | AR19: NA | AS19: NA | AT19: NA | AU19: NA | AV19: NA | AW19: NA | AX19: NA | AY19: NA | AZ19: NA | BA19: NA | BB19: NA | BC19: NA | BD19: NA | BE19: NA | BF19: NA | BG19: NA | BH19: NA | BI19: NA | BJ19: NA | BK19: NA | BL19: NA | BM19: NA | BN19: NA | BO19: NA | BP19: NA | BQ19: NA | BR19: NA | BS19: NA | BT19: NA | BU19: NA | BV19: NA | BW19: NA | BX19: NA | BY19: NA | BZ19: NA | CA19: NA | CB19: NA | CC19: NA | CD19: NA | CE19: NA | CF19: NA | CG19: NA | CH19: NA | CI19: NA
A20: Orphenadrine | B20: =VLOOKUP(A20,MOA!$C$2:$D$1253,2,FALSE) -> Acetylcholine receptor antagonist | C20: 0 | D20: 2 | E20: 0 | F20: NA | G20: NA | H20: NA | I20: NA | J20: NA | K20: NA | L20: NA | M20: NA | N20: NA | O20: NA | P20: NA | Q20: NA | R20: -0.32555992 | S20: NA | T20: NA | U20: NA | V20: NA | W20: NA | X20: NA | Y20: NA | Z20: NA | AA20: NA | AB20: NA | AC20: -0.60322362 | AD20: NA | AE20: NA | AF20: NA | AG20: NA | AH20: NA | AI20: NA | AJ20: NA | AK20: NA | AL20: NA | AM20: NA | AN20: NA | AO20: NA | AP20: NA | AQ20: NA | AR20: NA | AS20: NA | AT20: NA | AU20: NA | AV20: NA | AW20: NA | AX20: NA | AY20: NA | AZ20: NA | BA20: NA | BB20: NA | BC20: NA | BD20: NA | BE20: NA | BF20: NA | BG20: NA | BH20: NA | BI20: NA | BJ20: NA | BK20: NA | BL20: NA | BM20: NA | BN20: NA | BO20: NA | BP20: NA | BQ20: NA | BR20: NA | BS20: NA | BT20: NA | BU20: NA | BV20: NA | BW20: NA | BX20: NA | BY20: NA | BZ20: NA | CA20: NA | CB20: NA | CC20: NA | CD20: NA | CE20: NA | CF20: NA | CG20: NA | CH20: NA | CI20: NA
A21: Piperidolate | B21: =VLOOKUP(A21,MOA!$C$2:$D$1253,2,FALSE) -> Acetylcholine receptor antagonist | C21: 1 | D21: 2 | E21: 0.5 | F21: NA | G21: NA | H21: NA | I21: -0.50682016 | J21: NA | K21: NA | L21: NA | M21: NA | N21: NA | O21: NA | P21: NA | Q21: NA | R21: -0.59165574 | S21: NA | T21: NA | U21: NA | V21: NA | W21: NA | X21: NA | Y21: NA | Z21: NA | AA21: NA | AB21: NA | AC21: 0.40608082 | AD21: NA | AE21: NA | AF21: NA | AG21: NA | AH21: NA | AI21: NA | AJ21: NA | AK21: NA | AL21: NA | AM21: NA | AN21: NA | AO21: NA | AP21: NA | AQ21: NA | AR21: NA | AS21: NA | AT21: NA | AU21: NA | AV21: NA | AW21: NA | AX21: NA | AY21: NA | AZ21: NA | BA21: NA | BB21: NA | BC21: NA | BD21: NA | BE21: NA | BF21: NA | BG21: NA | BH21: NA | BI21: NA | BJ21: NA | BK21: NA | BL21: NA | BM21: NA | BN21: NA | BO21: NA | BP21: NA | BQ21: NA | BR21: NA | BS21: NA | BT21: NA | BU21: NA | BV21: NA | BW21: NA | BX21: NA | BY21: NA | BZ21: NA | CA21: NA | CB21: NA | CC21: NA | CD21: NA | CE21: NA | CF21: NA | CG21: NA | CH21: NA | CI21: NA
A22: Tropicamide | B22: =VLOOKUP(A22,MOA!$C$2:$D$1253,2,FALSE) -> Acetylcholine receptor antagonist | C22: 1 | D22: 1 | E22: 1 | F22: NA | G22: NA | H22: NA | I22: NA | J22: NA | K22: NA | L22: NA | M22: NA | N22: -0.52804223 | O22: NA | P22: NA | Q22: NA | R22: NA | S22: NA | T22: NA | U22: NA | V22: NA | W22: NA | X22: NA | Y22: NA | Z22: NA | AA22: NA | AB22: NA | AC22: NA | AD22: NA | AE22: NA | AF22: NA | AG22: NA | AH22: NA | AI22: NA | AJ22: 0.48504326 | AK22: NA | AL22: NA | AM22: NA | AN22: NA | AO22: NA | AP22: NA | AQ22: NA | AR22: NA | AS22: NA | AT22: NA | AU22: NA | AV22: NA | AW22: NA | AX22: NA | AY22: NA | AZ22: NA | BA22: NA | BB22: NA | BC22: NA | BD22: NA | BE22: NA | BF22: NA | BG22: NA | BH22: NA | BI22: NA | BJ22: NA | BK22: NA | BL22: NA | BM22: NA | BN22: NA | BO22: NA | BP22: NA | BQ22: NA | BR22: NA | BS22: NA | BT22: NA | BU22: NA | BV22: NA | BW22: NA | BX22: NA | BY22: NA | BZ22: NA | CA22: NA | CB22: NA | CC22: NA | CD22: NA | CE22: NA | CF22: NA | CG22: NA | CH22: NA | CI22: NA
A23: Hyoscyamine | B23: =VLOOKUP(A23,MOA!$C$2:$D$1253,2,FALSE) -> Acetylcholine receptor antagonist | C23: 1 | D23: 1 | E23: 1 | F23: NA | G23: NA | H23: NA | I23: NA | J23: NA | K23: NA | L23: NA | M23: NA | N23: NA | O23: NA | P23: NA | Q23: NA | R23: NA | S23: NA | T23: NA | U23: NA | V23: NA | W23: NA | X23: NA | Y23: NA | Z23: NA | AA23: NA | AB23: -0.45208921 | AC23: 0.38997428 | AD23: NA | AE23: NA | AF23: NA | AG23: NA | AH23: NA | AI23: NA | AJ23: NA | AK23: NA | AL23: NA | AM23: NA | AN23: NA | AO23: NA | AP23: NA | AQ23: NA | AR23: NA | AS23: NA | AT23: NA | AU23: NA | AV23: NA | AW23: NA | AX23: NA | AY23: NA | AZ23: NA | BA23: NA | BB23: NA | BC23: NA | BD23: NA | BE23: NA | BF23: NA | BG23: NA | BH23: NA | BI23: NA | BJ23: NA | BK23: NA | BL23: NA | BM23: NA | BN23: NA | BO23: NA | BP23: NA | BQ23: NA | BR23: NA | BS23: NA | BT23: NA | BU23: NA | BV23: NA | BW23: NA | BX23: NA | BY23: NA | BZ23: NA | CA23: NA | CB23: NA | CC23: NA | CD23: NA | CE23: NA | CF23: NA | CG23: NA | CH23: NA | CI23: NA
A24: Methixene | B24: =VLOOKUP(A24,MOA!$C$2:$D$1253,2,FALSE) -> Acetylcholine receptor antagonist | C24: 4 | D24: 1 | E24: 4 | F24: NA | G24: NA | H24: NA | I24: 0.53984535 | J24: NA | K24: NA | L24: NA | M24: NA | N24: NA | O24: NA | P24: NA | Q24: NA | R24: 0.46733335 | S24: NA | T24: NA | U24: NA | V24: NA | W24: NA | X24: NA | Y24: NA | Z24: NA | AA24: NA | AB24: -0.38926463 | AC24: 0.46604901 | AD24: NA | AE24: NA | AF24: NA | AG24: NA | AH24: NA | AI24: NA | AJ24: 0.63410351 | AK24: NA | AL24: NA | AM24: NA | AN24: NA | AO24: NA | AP24: NA | AQ24: NA | AR24: NA | AS24: NA | AT24: NA | AU24: NA | AV24: NA | AW24: NA | AX24: NA | AY24: NA | AZ24: NA | BA24: NA | BB24: NA | BC24: NA | BD24: NA | BE24: NA | BF24: NA | BG24: NA | BH24: NA | BI24: NA | BJ24: NA | BK24: NA | BL24: NA | BM24: NA | BN24: NA | BO24: NA | BP24: NA | BQ24: NA | BR24: NA | BS24: NA | BT24: NA | BU24: NA | BV24: NA | BW24: NA | BX24: NA | BY24: NA | BZ24: NA | CA24: NA | CB24: NA | CC24: NA | CD24: NA | CE24: NA | CF24: NA | CG24: NA | CH24: NA | CI24: NA
A25: Dicyclomine | B25: =VLOOKUP(A25,MOA!$C$2:$D$1253,2,FALSE) -> Acetylcholine receptor antagonist | C25: 1 | D25: 1 | E25: 1 | F25: NA | G25: NA | H25: NA | I25: NA | J25: NA | K25: NA | L25: NA | M25: NA | N25: NA | O25: NA | P25: NA | Q25: NA | R25: NA | S25: NA | T25: 0.44118632 | U25: NA | V25: NA | W25: NA | X25: NA | Y25: NA | Z25: NA | AA25: NA | AB25: NA | AC25: NA | AD25: NA | AE25: NA | AF25: NA | AG25: NA | AH25: NA | AI25: NA | AJ25: -0.38604561 | AK25: NA | AL25: NA | AM25: NA | AN25: NA | AO25: NA | AP25: NA | AQ25: NA | AR25: NA | AS25: NA | AT25: NA | AU25: NA | AV25: NA | AW25: NA | AX25: NA | AY25: NA | AZ25: NA | BA25: NA | BB25: NA | BC25: NA | BD25: NA | BE25: NA | BF25: NA | BG25: NA | BH25: NA | BI25: NA | BJ25: NA | BK25: NA | BL25: NA | BM25: NA | BN25: NA | BO25: NA | BP25: NA | BQ25: NA | BR25: NA | BS25: NA | BT25: NA | BU25: NA | BV25: NA | BW25: NA | BX25: NA | BY25: NA | BZ25: NA | CA25: NA | CB25: NA | CC25: NA | CD25: NA | CE25: NA | CF25: NA | CG25: NA | CH25: NA | CI25: NA
A26: Methantheline | B26: =VLOOKUP(A26,MOA!$C$2:$D$1253,2,FALSE) -> Acetylcholine receptor antagonist | C26: 3 | D26: 0 | E26: Inf | F26: NA | G26: NA | H26: NA | I26: NA | J26: NA | K26: NA | L26: NA | M26: NA | N26: 0.56082617 | O26: NA | P26: NA | Q26: NA | R26: NA | S26: NA | T26: NA | U26: NA | V26: NA | W26: NA | X26: NA | Y26: NA | Z26: NA | AA26: NA | AB26: NA | AC26: 0.49810701 | AD26: NA | AE26: NA | AF26: NA | AG26: NA | AH26: NA | AI26: NA | AJ26: 0.47553493 | AK26: NA | AL26: NA | AM26: NA | AN26: NA | AO26: NA | AP26: NA | AQ26: NA | AR26: NA | AS26: NA | AT26: NA | AU26: NA | AV26: NA | AW26: NA | AX26: NA | AY26: NA | AZ26: NA | BA26: NA | BB26: NA | BC26: NA | BD26: NA | BE26: NA | BF26: NA | BG26: NA | BH26: NA | BI26: NA | BJ26: NA | BK26: NA | BL26: NA | BM26: NA | BN26: NA | BO26: NA | BP26: NA | BQ26: NA | BR26: NA | BS26: NA | BT26: NA | BU26: NA | BV26: NA | BW26: NA | BX26: NA | BY26: NA | BZ26: NA | CA26: NA | CB26: NA | CC26: NA | CD26: NA | CE26: NA | CF26: NA | CG26: NA | CH26: NA | CI26: NA
A27: Darifenacin | B27: =VLOOKUP(A27,MOA!$C$2:$D$1253,2,FALSE) -> Acetylcholine receptor antagonist | C27: 3 | D27: 0 | E27: Inf | F27: NA | G27: NA | H27: NA | I27: NA | J27: NA | K27: NA | L27: NA | M27: NA | N27: NA | O27: NA | P27: NA | Q27: NA | R27: NA | S27: 0.4162904 | T27: NA | U27: NA | V27: NA | W27: NA | X27: NA | Y27: NA | Z27: NA | AA27: NA | AB27: 0.47300975 | AC27: 0.46915435 | AD27: NA | AE27: NA | AF27: NA | AG27: NA | AH27: NA | AI27: NA | AJ27: NA | AK27: NA | AL27: NA | AM27: NA | AN27: NA | AO27: NA | AP27: NA | AQ27: NA | AR27: NA | AS27: NA | AT27: NA | AU27: NA | AV27: NA | AW27: NA | AX27: NA | AY27: NA | AZ27: NA | BA27: NA | BB27: NA | BC27: NA | BD27: NA | BE27: NA | BF27: NA | BG27: NA | BH27: NA | BI27: NA | BJ27: NA | BK27: NA | BL27: NA | BM27: NA | BN27: NA | BO27: NA | BP27: NA | BQ27: NA | BR27: NA | BS27: NA | BT27: NA | BU27: NA | BV27: NA | BW27: NA | BX27: NA | BY27: NA | BZ27: NA | CA27: NA | CB27: NA | CC27: NA | CD27: NA | CE27: NA | CF27: NA | CG27: NA | CH27: NA | CI27: NA
A28: Strychnine | B28: =VLOOKUP(A28,MOA!$C$2:$D$1253,2,FALSE) -> Acetylcholine receptor antagonist | C28: 2 | D28: 0 | E28: Inf | F28: NA | G28: NA | H28: NA | I28: NA | J28: NA | K28: NA | L28: NA | M28: 0.39710513 | N28: NA | O28: NA | P28: NA | Q28: NA | R28: NA | S28: 0.38521218 | T28: NA | U28: NA | V28: NA | W28: NA | X28: NA | Y28: NA | Z28: NA | AA28: NA | AB28: NA | AC28: NA | AD28: NA | AE28: NA | AF28: NA | AG28: NA | AH28: NA | AI28: NA | AJ28: NA | AK28: NA | AL28: NA | AM28: NA | AN28: NA | AO28: NA | AP28: NA | AQ28: NA | AR28: NA | AS28: NA | AT28: NA | AU28: NA | AV28: NA | AW28: NA | AX28: NA | AY28: NA | AZ28: NA | BA28: NA | BB28: NA | BC28: NA | BD28: NA | BE28: NA | BF28: NA | BG28: NA | BH28: NA | BI28: NA | BJ28: NA | BK28: NA | BL28: NA | BM28: NA | BN28: NA | BO28: NA | BP28: NA | BQ28: NA | BR28: NA | BS28: NA | BT28: NA | BU28: NA | BV28: NA | BW28: NA | BX28: NA | BY28: NA | BZ28: NA | CA28: NA | CB28: NA | CC28: NA | CD28: NA | CE28: NA | CF28: NA | CG28: NA | CH28: NA | CI28: NA
A29: Boldine | B29: =VLOOKUP(A29,MOA!$C$2:$D$1253,2,FALSE) -> Acetylcholine receptor antagonist|Dopamine receptor antagonist | C29: 0 | D29: 2 | E29: 0 | F29: NA | G29: NA | H29: NA | I29: NA | J29: NA | K29: NA | L29: NA | M29: NA | N29: NA | O29: NA | P29: NA | Q29: NA | R29: -0.57494392 | S29: NA | T29: -0.51549864 | U29: NA | V29: NA | W29: NA | X29: NA | Y29: NA | Z29: NA | AA29: NA | AB29: NA | AC29: NA | AD29: NA | AE29: NA | AF29: NA | AG29: NA | AH29: NA | AI29: NA | AJ29: NA | AK29: NA | AL29: NA | AM29: NA | AN29: NA | AO29: NA | AP29: NA | AQ29: NA | AR29: NA | AS29: NA | AT29: NA | AU29: NA | AV29: NA | AW29: NA | AX29: NA | AY29: NA | AZ29: NA | BA29: NA | BB29: NA | BC29: NA | BD29: NA | BE29: NA | BF29: NA | BG29: NA | BH29: NA | BI29: NA | BJ29: NA | BK29: NA | BL29: NA | BM29: NA | BN29: NA | BO29: NA | BP29: NA | BQ29: NA | BR29: NA | BS29: NA | BT29: NA | BU29: NA | BV29: NA | BW29: NA | BX29: NA | BY29: NA | BZ29: NA | CA29: NA | CB29: NA | CC29: NA | CD29: NA | CE29: NA | CF29: NA | CG29: NA | CH29: NA | CI29: NA
A30: Herniarin | B30: =VLOOKUP(A30,MOA!$C$2:$D$1253,2,FALSE) -> Acetylcholinesterase inhibitor | C30: 1 | D30: 1 | E30: 1 | F30: NA | G30: NA | H30: NA | I30: NA | J30: NA | K30: NA | L30: NA | M30: NA | N30: NA | O30: NA | P30: NA | Q30: NA | R30: NA | S30: NA | T30: -0.52947784 | U30: NA | V30: NA | W30: NA | X30: NA | Y30: NA | Z30: NA | AA30: NA | AB30: 0.54048152 | AC30: NA | AD30: NA | AE30: NA | AF30: NA | AG30: NA | AH30: NA | AI30: NA | AJ30: NA | AK30: NA | AL30: NA | AM30: NA | AN30: NA | AO30: NA | AP30: NA | AQ30: NA | AR30: NA | AS30: NA | AT30: NA | AU30: NA | AV30: NA | AW30: NA | AX30: NA | AY30: NA | AZ30: NA | BA30: NA | BB30: NA | BC30: NA | BD30: NA | BE30: NA | BF30: NA | BG30: NA | BH30: NA | BI30: NA | BJ30: NA | BK30: NA | BL30: NA | BM30: NA | BN30: NA | BO30: NA | BP30: NA | BQ30: NA | BR30: NA | BS30: NA | BT30: NA | BU30: NA | BV30: NA | BW30: NA | BX30: NA | BY30: NA | BZ30: NA | CA30: NA | CB30: NA | CC30: NA | CD30: NA | CE30: NA | CF30: NA | CG30: NA | CH30: NA | CI30: NA
A31: Alpha-Solanine | B31: =VLOOKUP(A31,MOA!$C$2:$D$1253,2,FALSE) -> Acetylcholinesterase inhibitor | C31: 3 | D31: 1 | E31: 3 | F31: NA | G31: NA | H31: NA | I31: NA | J31: NA | K31: 0.61874556 | L31: 0.52383919 | M31: -0.44476543 | N31: NA | O31: NA | P31: NA | Q31: NA | R31: NA | S31: NA | T31: NA | U31: NA | V31: NA | W31: NA | X31: NA | Y31: NA | Z31: NA | AA31: NA | AB31: NA | AC31: NA | AD31: NA | AE31: NA | AF31: NA | AG31: NA | AH31: NA | AI31: NA | AJ31: NA | AK31: NA | AL31: NA | AM31: NA | AN31: NA | AO31: 0.38975935 | AP31: NA | AQ31: NA | AR31: NA | AS31: NA | AT31: NA | AU31: NA | AV31: NA | AW31: NA | AX31: NA | AY31: NA | AZ31: NA | BA31: NA | BB31: NA | BC31: NA | BD31: NA | BE31: NA | BF31: NA | BG31: NA | BH31: NA | BI31: NA | BJ31: NA | BK31: NA | BL31: NA | BM31: NA | BN31: NA | BO31: NA | BP31: NA | BQ31: NA | BR31: NA | BS31: NA | BT31: NA | BU31: NA | BV31: NA | BW31: NA | BX31: NA | BY31: NA | BZ31: NA | CA31: NA | CB31: NA | CC31: NA | CD31: NA | CE31: NA | CF31: NA | CG31: NA | CH31: NA | CI31: NA
A32: Buddleoflavonoloside | B32: =VLOOKUP(A32,MOA!$C$2:$D$1253,2,FALSE) -> Acetylcholinesterase inhibitor | C32: 1 | D32: 1 | E32: 1 | F32: NA | G32: NA | H32: NA | I32: NA | J32: NA | K32: NA | L32: NA | M32: NA | N32: NA | O32: NA | P32: NA | Q32: NA | R32: 0.33732669 | S32: NA | T32: -0.40179012 | U32: NA | V32: NA | W32: NA | X32: NA | Y32: NA | Z32: NA | AA32: NA | AB32: NA | AC32: NA | AD32: NA | AE32: NA | AF32: NA | AG32: NA | AH32: NA | AI32: NA | AJ32: NA | AK32: NA | AL32: NA | AM32: NA | AN32: NA | AO32: NA | AP32: NA | AQ32: NA | AR32: NA | AS32: NA | AT32: NA | AU32: NA | AV32: NA | AW32: NA | AX32: NA | AY32: NA | AZ32: NA | BA32: NA | BB32: NA | BC32: NA | BD32: NA | BE32: NA | BF32: NA | BG32: NA | BH32: NA | BI32: NA | BJ32: NA | BK32: NA | BL32: NA | BM32: NA | BN32: NA | BO32: NA | BP32: NA | BQ32: NA | BR32: NA | BS32: NA | BT32: NA | BU32: NA | BV32: NA | BW32: NA | BX32: NA | BY32: NA | BZ32: NA | CA32: NA | CB32: NA | CC32: NA | CD32: NA | CE32: NA | CF32: NA | CG32: NA | CH32: NA | CI32: NA
A33: Tacrine | B33: =VLOOKUP(A33,MOA!$C$2:$D$1253,2,FALSE) -> Acetylcholinesterase inhibitor | C33: 1 | D33: 1 | E33: 1 | F33: NA | G33: NA | H33: NA | I33: NA | J33: NA | K33: NA | L33: NA | M33: NA | N33: NA | O33: NA | P33: NA | Q33: NA | R33: -0.39904641 | S33: NA | T33: NA | U33: NA | V33: NA | W33: NA | X33: NA | Y33: NA | Z33: NA | AA33: NA | AB33: NA | AC33: 0.4265655 | AD33: NA | AE33: NA | AF33: NA | AG33: NA | AH33: NA | AI33: NA | AJ33: NA | AK33: NA | AL33: NA | AM33: NA | AN33: NA | AO33: NA | AP33: NA | AQ33: NA | AR33: NA | AS33: NA | AT33: NA | AU33: NA | AV33: NA | AW33: NA | AX33: NA | AY33: NA | AZ33: NA | BA33: NA | BB33: NA | BC33: NA | BD33: NA | BE33: NA | BF33: NA | BG33: NA | BH33: NA | BI33: NA | BJ33: NA | BK33: NA | BL33: NA | BM33: NA | BN33: NA | BO33: NA | BP33: NA | BQ33: NA | BR33: NA | BS33: NA | BT33: NA | BU33: NA | BV33: NA | BW33: NA | BX33: NA | BY33: NA | BZ33: NA | CA33: NA | CB33: NA | CC33: NA | CD33: NA | CE33: NA | CF33: NA | CG33: NA | CH33: NA | CI33: NA
A34: Neostigmine | B34: =VLOOKUP(A34,MOA!$C$2:$D$1253,2,FALSE) -> Acetylcholinesterase inhibitor | C34: 1 | D34: 1 | E34: 1 | F34: NA | G34: NA | H34: NA | I34: NA | J34: NA | K34: NA | L34: NA | M34: NA | N34: NA | O34: NA | P34: NA | Q34: NA | R34: NA | S34: NA | T34: NA | U34: NA | V34: NA | W34: NA | X34: NA | Y34: NA | Z34: NA | AA34: NA | AB34: NA | AC34: 0.55782509 | AD34: NA | AE34: NA | AF34: NA | AG34: NA | AH34: NA | AI34: NA | AJ34: NA | AK34: NA | AL34: NA | AM34: NA | AN34: NA | AO34: NA | AP34: NA | AQ34: NA | AR34: NA | AS34: NA | AT34: NA | AU34: NA | AV34: NA | AW34: NA | AX34: NA | AY34: NA | AZ34: NA | BA34: NA | BB34: NA | BC34: NA | BD34: NA | BE34: NA | BF34: NA | BG34: NA | BH34: -0.39623137 | BI34: NA | BJ34: NA | BK34: NA | BL34: NA | BM34: NA | BN34: NA | BO34: NA | BP34: NA | BQ34: NA | BR34: NA | BS34: NA | BT34: NA | BU34: NA | BV34: NA | BW34: NA | BX34: NA | BY34: NA | BZ34: NA | CA34: NA | CB34: NA | CC34: NA | CD34: NA | CE34: NA | CF34: NA | CG34: NA | CH34: NA | CI34: NA
A35: galantamine | B35: =IFERROR(VLOOKUP(A35, [1]Overall!$A$2:$B$1442, 2, FALSE), IFERROR(VLOOKUP(A35, [1]Female!$A$2:$B$1276, 2, FALSE), IFERROR(VLOOKUP(A35, [1]Male!$A$2:$B$1529, 2, FALSE), "Not Found"))) -> Acetylcholinesterase inhibitor | C35: 4 | D35: 0 | E35: Inf | F35: NA | G35: NA | H35: NA | I35: 0.40880426 | J35: NA | K35: 0.41149745 | L35: NA | M35: NA | N35: NA | O35: NA | P35: NA | Q35: NA | R35: 0.58412324 | S35: NA | T35: NA | U35: NA | V35: NA | W35: NA | X35: NA | Y35: NA | Z35: NA | AA35: NA | AB35: NA | AC35: 0.47517732 | AD35: NA | AE35: NA | AF35: NA | AG35: NA | AH35: NA | AI35: NA | AJ35: NA | AK35: NA | AL35: NA | AM35: NA | AN35: NA | AO35: NA | AP35: NA | AQ35: NA | AR35: NA | AS35: NA | AT35: NA | AU35: NA | AV35: NA | AW35: NA | AX35: NA | AY35: NA | AZ35: NA | BA35: NA | BB35: NA | BC35: NA | BD35: NA | BE35: NA | BF35: NA | BG35: NA | BH35: NA | BI35: NA | BJ35: NA | BK35: NA | BL35: NA | BM35: NA | BN35: NA | BO35: NA | BP35: NA | BQ35: NA | BR35: NA | BS35: NA | BT35: NA | BU35: NA | BV35: NA | BW35: NA | BX35: NA | BY35: NA | BZ35: NA | CA35: NA | CB35: NA | CC35: NA | CD35: NA | CE35: NA | CF35: NA | CG35: NA | CH35: NA | CI35: NA
A36: Physostigmine | B36: =VLOOKUP(A36,MOA!$C$2:$D$1253,2,FALSE) -> Acetylcholinesterase inhibitor|Cholinesterase inhibitor | C36: 1 | D36: 1 | E36: 1 | F36: NA | G36: NA | H36: NA | I36: NA | J36: NA | K36: NA | L36: NA | M36: 0.473184 | N36: NA | O36: NA | P36: NA | Q36: NA | R36: NA | S36: NA | T36: NA | U36: NA | V36: NA | W36: NA | X36: NA | Y36: NA | Z36: NA | AA36: NA | AB36: NA | AC36: -0.38874126 | AD36: NA | AE36: NA | AF36: NA | AG36: NA | AH36: NA | AI36: NA | AJ36: NA | AK36: NA | AL36: NA | AM36: NA | AN36: NA | AO36: NA | AP36: NA | AQ36: NA | AR36: NA | AS36: NA | AT36: NA | AU36: NA | AV36: NA | AW36: NA | AX36: NA | AY36: NA | AZ36: NA | BA36: NA | BB36: NA | BC36: NA | BD36: NA | BE36: NA | BF36: NA | BG36: NA | BH36: NA | BI36: NA | BJ36: NA | BK36: NA | BL36: NA | BM36: NA | BN36: NA | BO36: NA | BP36: NA | BQ36: NA | BR36: NA | BS36: NA | BT36: NA | BU36: NA | BV36: NA | BW36: NA | BX36: NA | BY36: NA | BZ36: NA | CA36: NA | CB36: NA | CC36: NA | CD36: NA | CE36: NA | CF36: NA | CG36: NA | CH36: NA | CI36: NA
A37: Secnidazole | B37: =VLOOKUP(A37,MOA!$C$2:$D$1253,2,FALSE) -> Acetylcholinesterase inhibitor|Microtubule inhibitor | C37: 3 | D37: 0 | E37: Inf | F37: NA | G37: NA | H37: NA | I37: NA | J37: NA | K37: NA | L37: NA | M37: NA | N37: NA | O37: NA | P37: NA | Q37: NA | R37: NA | S37: 0.53126611 | T37: NA | U37: NA | V37: NA | W37: NA | X37: NA | Y37: NA | Z37: NA | AA37: NA | AB37: 0.44754154 | AC37: NA | AD37: NA | AE37: NA | AF37: NA | AG37: NA | AH37: NA | AI37: NA | AJ37: NA | AK37: NA | AL37: NA | AM37: NA | AN37: NA | AO37: NA | AP37: NA | AQ37: NA | AR37: NA | AS37: NA | AT37: NA | AU37: NA | AV37: NA | AW37: NA | AX37: NA | AY37: NA | AZ37: NA | BA37: NA | BB37: NA | BC37: NA | BD37: NA | BE37: NA | BF37: NA | BG37: NA | BH37: 0.42083938 | BI37: NA | BJ37: NA | BK37: NA | BL37: NA | BM37: NA | BN37: NA | BO37: NA | BP37: NA | BQ37: NA | BR37: NA | BS37: NA | BT37: NA | BU37: NA | BV37: NA | BW37: NA | BX37: NA | BY37: NA | BZ37: NA | CA37: NA | CB37: NA | CC37: NA | CD37: NA | CE37: NA | CF37: NA | CG37: NA | CH37: NA | CI37: NA
A38: Desoxypeganine | B38: =VLOOKUP(A38,MOA!$C$2:$D$1253,2,FALSE) -> Acetylcholinesterase inhibitor|Monoamine oxidase inhibitor | C38: 1 | D38: 3 | E38: 0.33333333 | F38: NA | G38: NA | H38: NA | I38: NA | J38: NA | K38: 0.43848364 | L38: NA | M38: NA | N38: NA | O38: NA | P38: NA | Q38: NA | R38: -0.38638536 | S38: NA | T38: NA | U38: NA | V38: NA | W38: NA | X38: NA | Y38: NA | Z38: NA | AA38: NA | AB38: NA | AC38: -0.3625605 | AD38: NA | AE38: NA | AF38: NA | AG38: NA | AH38: NA | AI38: NA | AJ38: NA | AK38: NA | AL38: NA | AM38: NA | AN38: NA | AO38: NA | AP38: NA | AQ38: NA | AR38: NA | AS38: NA | AT38: NA | AU38: NA | AV38: NA | AW38: NA | AX38: NA | AY38: NA | AZ38: NA | BA38: NA | BB38: NA | BC38: NA | BD38: NA | BE38: NA | BF38: NA | BG38: NA | BH38: -0.4653147 | BI38: NA | BJ38: NA | BK38: NA | BL38: NA | BM38: NA | BN38: NA | BO38: NA | BP38: NA | BQ38: NA | BR38: NA | BS38: NA | BT38: NA | BU38: NA | BV38: NA | BW38: NA | BX38: NA | BY38: NA | BZ38: NA | CA38: NA | CB38: NA | CC38: NA | CD38: NA | CE38: NA | CF38: NA | CG38: NA | CH38: NA | CI38: NA
A39: Ercalcitriol | B39: =IFERROR(VLOOKUP(A39, [1]Overall!$A$2:$B$1442, 2, FALSE), IFERROR(VLOOKUP(A39, [1]Female!$A$2:$B$1276, 2, FALSE), IFERROR(VLOOKUP(A39, [1]Male!$A$2:$B$1529, 2, FALSE), "Not Found"))) -> Active form of vitamin D3, regulates calcium homeostasis | C39: 3 | D39: 0 | E39: Inf | F39: NA | G39: NA | H39: NA | I39: NA | J39: NA | K39: NA | L39: NA | M39: NA | N39: NA | O39: NA | P39: NA | Q39: NA | R39: NA | S39: 0.47496622 | T39: NA | U39: NA | V39: NA | W39: NA | X39: NA | Y39: NA | Z39: NA | AA39: NA | AB39: 0.5398644 | AC39: NA | AD39: NA | AE39: NA | AF39: NA | AG39: NA | AH39: NA | AI39: NA | AJ39: NA | AK39: NA | AL39: NA | AM39: NA | AN39: NA | AO39: NA | AP39: NA | AQ39: NA | AR39: NA | AS39: NA | AT39: NA | AU39: NA | AV39: NA | AW39: 0.3876885 | AX39: NA | AY39: NA | AZ39: NA | BA39: NA | BB39: NA | BC39: NA | BD39: NA | BE39: NA | BF39: NA | BG39: NA | BH39: NA | BI39: NA | BJ39: NA | BK39: NA | BL39: NA | BM39: NA | BN39: NA | BO39: NA | BP39: NA | BQ39: NA | BR39: NA | BS39: NA | BT39: NA | BU39: NA | BV39: NA | BW39: NA | BX39: NA | BY39: NA | BZ39: NA | CA39: NA | CB39: NA | CC39: NA | CD39: NA | CE39: NA | CF39: NA | CG39: NA | CH39: NA | CI39: NA
A40: IB-MECA | B40: =VLOOKUP(A40,MOA!$C$2:$D$1253,2,FALSE) -> Adenosine A3 receptor agonist | C40: 1 | D40: 2 | E40: 0.5 | F40: NA | G40: NA | H40: NA | I40: -0.56785225 | J40: NA | K40: NA | L40: NA | M40: NA | N40: NA | O40: NA | P40: NA | Q40: NA | R40: NA | S40: NA | T40: NA | U40: NA | V40: NA | W40: NA | X40: NA | Y40: NA | Z40: NA | AA40: NA | AB40: NA | AC40: NA | AD40: NA | AE40: NA | AF40: NA | AG40: NA | AH40: NA | AI40: NA | AJ40: NA | AK40: NA | AL40: NA | AM40: NA | AN40: NA | AO40: NA | AP40: NA | AQ40: NA | AR40: NA | AS40: NA | AT40: NA | AU40: NA | AV40: NA | AW40: 0.4158721 | AX40: NA | AY40: NA | AZ40: NA | BA40: NA | BB40: NA | BC40: NA | BD40: NA | BE40: NA | BF40: NA | BG40: NA | BH40: -0.61519261 | BI40: NA | BJ40: NA | BK40: NA | BL40: NA | BM40: NA | BN40: NA | BO40: NA | BP40: NA | BQ40: NA | BR40: NA | BS40: NA | BT40: NA | BU40: NA | BV40: NA | BW40: NA | BX40: NA | BY40: NA | BZ40: NA | CA40: NA | CB40: NA | CC40: NA | CD40: NA | CE40: NA | CF40: NA | CG40: NA | CH40: NA | CI40: NA
...

Sheet Female
A1: compound | B1: MOA | C1: num_concordant | D1: num_discordant | E1: ratio | F1: RMGI | G1: EFO27 | H1: RMUGS | I1: HA1E | J1: SNGM | K1: HEPG2 | L1: NPC | M1: SKB | N1: VCAP | O1: SKLU1 | P1: COV644 | Q1: HEC108 | R1: MCF7 | S1: A375 | T1: HCC515 | U1: MDAMB231 | V1: LNCAP | W1: BT20 | X1: MCF10A | Y1: HME1 | Z1: ASC | AA1: SKBR3 | AB1: HT29 | AC1: PC3 | AD1: HS578T | AE1: SW620 | AF1: SW480 | AG1: CORL23 | AH1: OV7 | AI1: THP1 | AJ1: A549 | AK1: HCT116 | AL1: LOVO | AM1: CD34 | AN1: NOMO1 | AO1: PHH | AP1: NPC.TAK | AQ1: HUVEC | AR1: HEK293T | AS1: RKO | AT1: PL21 | AU1: ASC.C | AV1: SKL | AW1: HELA | AX1: SW948 | AY1: SNU1040 | AZ1: TYKNU | BA1: NCIH1694 | BB1: AGS | BC1: HUH7 | BD1: DV90 | BE1: SKMEL1 | BF1: U937 | BG1: T3M10 | BH1: YAPC | BI1: NCIH2073 | BJ1: MDST8 | BK1: NKDBA | BL1: NEU | BM1: HL60 | BN1: SNUC4 | BO1: U266 | BP1: HUES3 | BQ1: SKL.C | BR1: HCC15 | BS1: A673 | BT1: WSUDLCL2 | BU1: SNUC5 | BV1: SKMEL28 | BW1: NCIH1836 | BX1: NPC.CAS9 | BY1: H1299 | BZ1: JHUEM2 | CA1: FIBRNPC | CB1: NCIH508 | CC1: NCIH596 | CD1: SKM1 | CE1: MNEU.E | CF1: JURKAT | CG1: HT115 | CH1: CL34 | CI1: HS27A
A2: Ursolic acid | B2: =VLOOKUP(A2,MOA!$C$2333:$D$3565,2,FALSE) -> 11-beta hydroxysteroid dehydrogenase inhibitor|Acetylcholinesterase inhibitor|Caspase inhibitor|HIV protease inhibitor|Lipid peroxidase inhibitor|Quorum sensing signaling modulator|Steryl sulfatase inhibitor|Tyrosine phosphatase inhibitor|ATPase inhibitor|NFkB pathway inhibitor|STAT inhibitor | C2: 3 | D2: 1 | E2: 3 | F2: NA | G2: NA | H2: NA | I2: 0.37465619 | J2: NA | K2: NA | L2: NA | M2: NA | N2: NA | O2: NA | P2: NA | Q2: NA | R2: NA | S2: NA | T2: NA | U2: NA | V2: NA | W2: NA | X2: NA | Y2: NA | Z2: NA | AA2: NA | AB2: NA | AC2: NA | AD2: NA | AE2: NA | AF2: NA | AG2: NA | AH2: NA | AI2: NA | AJ2: NA | AK2: NA | AL2: NA | AM2: NA | AN2: NA | AO2: NA | AP2: NA | AQ2: NA | AR2: NA | AS2: NA | AT2: -0.50046254 | AU2: NA | AV2: NA | AW2: NA | AX2: NA | AY2: NA | AZ2: NA | BA2: NA | BB2: NA | BC2: NA | BD2: NA | BE2: NA | BF2: NA | BG2: NA | BH2: 0.41838348 | BI2: NA | BJ2: NA | BK2: NA | BL2: NA | BM2: NA | BN2: NA | BO2: NA | BP2: NA | BQ2: NA | BR2: NA | BS2: 0.32377643 | BT2: NA | BU2: NA | BV2: NA | BW2: NA | BX2: NA | BY2: NA | BZ2: NA | CA2: NA | CB2: NA | CC2: NA | CD2: NA | CE2: NA | CF2: NA | CG2: NA | CH2: NA | CI2: NA
A3: Carbenoxolone | B3: =VLOOKUP(A3,MOA!$C$2333:$D$3565,2,FALSE) -> 11-beta-HSD1 inhibitor | C3: 0 | D3: 2 | E3: 0 | F3: NA | G3: NA | H3: NA | I3: NA | J3: NA | K3: -0.4922964 | L3: NA | M3: NA | N3: NA | O3: NA | P3: NA | Q3: NA | R3: NA | S3: NA | T3: NA | U3: NA | V3: NA | W3: NA | X3: NA | Y3: NA | Z3: NA | AA3: NA | AB3: NA | AC3: -0.4180997 | AD3: NA | AE3: NA | AF3: NA | AG3: NA | AH3: NA | AI3: NA | AJ3: NA | AK3: NA | AL3: NA | AM3: NA | AN3: NA | AO3: NA | AP3: NA | AQ3: NA | AR3: NA | AS3: NA | AT3: NA | AU3: NA | AV3: NA | AW3: NA | AX3: NA | AY3: NA | AZ3: NA | BA3: NA | BB3: NA | BC3: NA | BD3: NA | BE3: NA | BF3: NA | BG3: NA | BH3: NA | BI3: NA | BJ3: NA | BK3: NA | BL3: NA | BM3: NA | BN3: NA | BO3: NA | BP3: NA | BQ3: NA | BR3: NA | BS3: NA | BT3: NA | BU3: NA | BV3: NA | BW3: NA | BX3: NA | BY3: NA | BZ3: NA | CA3: NA | CB3: NA | CC3: NA | CD3: NA | CE3: NA | CF3: NA | CG3: NA | CH3: NA | CI3: NA
A4: Chenodiol | B4: =VLOOKUP(A4,MOA!$C$2333:$D$3565,2,FALSE) -> 11-beta-HSD1 inhibitor|FXR agonist | C4: 1 | D4: 1 | E4: 1 | F4: NA | G4: NA | H4: NA | I4: NA | J4: NA | K4: NA | L4: NA | M4: NA | N4: NA | O4: NA | P4: NA | Q4: NA | R4: NA | S4: NA | T4: NA | U4: NA | V4: NA | W4: NA | X4: NA | Y4: NA | Z4: NA | AA4: NA | AB4: -0.57388365 | AC4: NA | AD4: NA | AE4: NA | AF4: NA | AG4: NA | AH4: NA | AI4: NA | AJ4: 0.49514328 | AK4: NA | AL4: NA | AM4: NA | AN4: NA | AO4: NA | AP4: NA | AQ4: NA | AR4: NA | AS4: NA | AT4: NA | AU4: NA | AV4: NA | AW4: NA | AX4: NA | AY4: NA | AZ4: NA | BA4: NA | BB4: NA | BC4: NA | BD4: NA | BE4: NA | BF4: NA | BG4: NA | BH4: NA | BI4: NA | BJ4: NA | BK4: NA | BL4: NA | BM4: NA | BN4: NA | BO4: NA | BP4: NA | BQ4: NA | BR4: NA | BS4: NA | BT4: NA | BU4: NA | BV4: NA | BW4: NA | BX4: NA | BY4: NA | BZ4: NA | CA4: NA | CB4: NA | CC4: NA | CD4: NA | CE4: NA | CF4: NA | CG4: NA | CH4: NA | CI4: NA
A5: Carfilzomib (PR-171) | B5: =VLOOKUP(A5,MOA!$C$2333:$D$3565,2,FALSE) -> 26S proteosome inhibitor | C5: 4 | D5: 0 | E5: Inf | F5: NA | G5: NA | H5: NA | I5: NA | J5: NA | K5: NA | L5: NA | M5: NA | N5: NA | O5: NA | P5: NA | Q5: NA | R5: 0.42255179 | S5: 0.42041668 | T5: NA | U5: NA | V5: NA | W5: NA | X5: NA | Y5: NA | Z5: NA | AA5: NA | AB5: NA | AC5: 0.48314752 | AD5: NA | AE5: NA | AF5: NA | AG5: NA | AH5: NA | AI5: NA | AJ5: NA | AK5: NA | AL5: NA | AM5: NA | AN5: NA | AO5: NA | AP5: NA | AQ5: NA | AR5: NA | AS5: NA | AT5: NA | AU5: NA | AV5: NA | AW5: NA | AX5: NA | AY5: NA | AZ5: NA | BA5: NA | BB5: NA | BC5: NA | BD5: NA | BE5: NA | BF5: NA | BG5: NA | BH5: 0.52272042 | BI5: NA | BJ5: NA | BK5: NA | BL5: NA | BM5: NA | BN5: NA | BO5: NA | BP5: NA | BQ5: NA | BR5: NA | BS5: NA | BT5: NA | BU5: NA | BV5: NA | BW5: NA | BX5: NA | BY5: NA | BZ5: NA | CA5: NA | CB5: NA | CC5: NA | CD5: NA | CE5: NA | CF5: NA | CG5: NA | CH5: NA | CI5: NA
A6: tropisetron | B6: =IFERROR(VLOOKUP(A6, [1]Overall!$A$2:$B$1442, 2, FALSE), IFERROR(VLOOKUP(A6, [1]Female!$A$2:$B$1276, 2, FALSE), IFERROR(VLOOKUP(A6, [1]Male!$A$2:$B$1529, 2, FALSE), "Not Found"))) -> 5-HT3 receptor antagonist | C6: 1 | D6: 3 | E6: 0.33333333 | F6: NA | G6: NA | H6: NA | I6: -0.38904055 | J6: NA | K6: NA | L6: NA | M6: NA | N6: NA | O6: NA | P6: NA | Q6: NA | R6: NA | S6: 0.37990917 | T6: NA | U6: NA | V6: NA | W6: NA | X6: NA | Y6: NA | Z6: NA | AA6: NA | AB6: -0.34626429 | AC6: NA | AD6: NA | AE6: NA | AF6: NA | AG6: NA | AH6: NA | AI6: NA | AJ6: NA | AK6: NA | AL6: NA | AM6: NA | AN6: NA | AO6: NA | AP6: NA | AQ6: NA | AR6: NA | AS6: NA | AT6: NA | AU6: NA | AV6: NA | AW6: -0.49203935 | AX6: NA | AY6: NA | AZ6: NA | BA6: NA | BB6: NA | BC6: NA | BD6: NA | BE6: NA | BF6: NA | BG6: NA | BH6: NA | BI6: NA | BJ6: NA | BK6: NA | BL6: NA | BM6: NA | BN6: NA | BO6: NA | BP6: NA | BQ6: NA | BR6: NA | BS6: NA | BT6: NA | BU6: NA | BV6: NA | BW6: NA | BX6: NA | BY6: NA | BZ6: NA | CA6: NA | CB6: NA | CC6: NA | CD6: NA | CE6: NA | CF6: NA | CG6: NA | CH6: NA | CI6: NA
A7: Nilotinib | B7: =VLOOKUP(A7,MOA!$C$2333:$D$3565,2,FALSE) -> Abl kinase inhibitor|Bcr-Abl kinase inhibitor | C7: 9 | D7: 5 | E7: 1.8 | F7: NA | G7: NA | H7: NA | I7: 0.54959045 | J7: NA | K7: 0.38174614 | L7: NA | M7: NA | N7: 0.50296308 | O7: NA | P7: NA | Q7: NA | R7: -0.39337724 | S7: 0.46937462 | T7: 0.33699724 | U7: 0.50473207 | V7: NA | W7: 0.34095172 | X7: -0.48516985 | Y7: NA | Z7: NA | AA7: -0.50595653 | AB7: -0.39339338 | AC7: 0.51431319 | AD7: -0.5220008 | AE7: NA | AF7: NA | AG7: NA | AH7: NA | AI7: NA | AJ7: 0.48430571 | AK7: NA | AL7: NA | AM7: NA | AN7: NA | AO7: NA | AP7: NA | AQ7: NA | AR7: NA | AS7: NA | AT7: NA | AU7: NA | AV7: NA | AW7: NA | AX7: NA | AY7: NA | AZ7: NA | BA7: NA | BB7: NA | BC7: NA | BD7: NA | BE7: NA | BF7: NA | BG7: NA | BH7: NA | BI7: NA | BJ7: NA | BK7: NA | BL7: NA | BM7: NA | BN7: NA | BO7: NA | BP7: NA | BQ7: NA | BR7: NA | BS7: NA | BT7: NA | BU7: NA | BV7: NA | BW7: NA | BX7: NA | BY7: NA | BZ7: NA | CA7: NA | CB7: NA | CC7: NA | CD7: NA | CE7: NA | CF7: NA | CG7: NA | CH7: NA | CI7: NA
A8: Bosutinib | B8: =VLOOKUP(A8,MOA!$C$2333:$D$3565,2,FALSE) -> Abl kinase inhibitor|Bcr-Abl kinase inhibitor|Src inhibitor | C8: 5 | D8: 7 | E8: 0.71428571 | F8: NA | G8: NA | H8: NA | I8: 0.45041016 | J8: NA | K8: -0.44976935 | L8: 0.43236362 | M8: NA | N8: NA | O8: NA | P8: NA | Q8: NA | R8: 0.46528754 | S8: NA | T8: -0.38949471 | U8: NA | V8: NA | W8: NA | X8: NA | Y8: NA | Z8: 0.5155075 | AA8: NA | AB8: -0.45675392 | AC8: NA | AD8: NA | AE8: NA | AF8: NA | AG8: NA | AH8: NA | AI8: NA | AJ8: -0.41447485 | AK8: NA | AL8: NA | AM8: NA | AN8: NA | AO8: NA | AP8: NA | AQ8: -0.47174715 | AR8: NA | AS8: NA | AT8: NA | AU8: NA | AV8: NA | AW8: NA | AX8: NA | AY8: NA | AZ8: NA | BA8: NA | BB8: NA | BC8: NA | BD8: NA | BE8: NA | BF8: NA | BG8: NA | BH8: NA | BI8: NA | BJ8: NA | BK8: NA | BL8: 0.40162435 | BM8: NA | BN8: NA | BO8: NA | BP8: NA | BQ8: -0.33492484 | BR8: NA | BS8: NA | BT8: NA | BU8: NA | BV8: NA | BW8: NA | BX8: NA | BY8: NA | BZ8: NA | CA8: NA | CB8: NA | CC8: NA | CD8: NA | CE8: NA | CF8: -0.33367304 | CG8: NA | CH8: NA | CI8: NA
A9: Avasimibe | B9: =IFERROR(VLOOKUP(A9, [1]Overall!$A$2:$B$1442, 2, FALSE), IFERROR(VLOOKUP(A9, [1]Female!$A$2:$B$1276, 2, FALSE), IFERROR(VLOOKUP(A9, [1]Male!$A$2:$B$1529, 2, FALSE), "Not Found"))) -> ACAT inhibitor, lowers cholesterol | C9: 4 | D9: 0 | E9: Inf | F9: NA | G9: NA | H9: NA | I9: NA | J9: NA | K9: NA | L9: NA | M9: NA | N9: NA | O9: NA | P9: NA | Q9: NA | R9: NA | S9: 0.57616455 | T9: NA | U9: NA | V9: NA | W9: NA | X9: NA | Y9: NA | Z9: NA | AA9: NA | AB9: 0.51293966 | AC9: 0.38936718 | AD9: NA | AE9: NA | AF9: NA | AG9: NA | AH9: NA | AI9: NA | AJ9: NA | AK9: NA | AL9: NA | AM9: NA | AN9: NA | AO9: NA | AP9: NA | AQ9: NA | AR9: NA | AS9: NA | AT9: NA | AU9: NA | AV9: NA | AW9: 0.38788032 | AX9: NA | AY9: NA | AZ9: NA | BA9: NA | BB9: NA | BC9: NA | BD9: NA | BE9: NA | BF9: NA | BG9: NA | BH9: NA | BI9: NA | BJ9: NA | BK9: NA | BL9: NA | BM9: NA | BN9: NA | BO9: NA | BP9: NA | BQ9: NA | BR9: NA | BS9: NA | BT9: NA | BU9: NA | BV9: NA | BW9: NA | BX9: NA | BY9: NA | BZ9: NA | CA9: NA | CB9: NA | CC9: NA | CD9: NA | CE9: NA | CF9: NA | CG9: NA | CH9: NA | CI9: NA
A10: Piracetam | B10: =VLOOKUP(A10,MOA!$C$2333:$D$3565,2,FALSE) -> Acetylcholine receptor agonist | C10: 0 | D10: 3 | E10: 0 | F10: NA | G10: NA | H10: NA | I10: NA | J10: NA | K10: NA | L10: NA | M10: NA | N10: NA | O10: NA | P10: NA | Q10: NA | R10: -0.39999988 | S10: NA | T10: NA | U10: NA | V10: NA | W10: NA | X10: NA | Y10: NA | Z10: NA | AA10: NA | AB10: -0.56694714 | AC10: NA | AD10: NA | AE10: NA | AF10: NA | AG10: NA | AH10: NA | AI10: NA | AJ10: NA | AK10: NA | AL10: NA | AM10: NA | AN10: NA | AO10: NA | AP10: NA | AQ10: NA | AR10: NA | AS10: NA | AT10: NA | AU10: NA | AV10: NA | AW10: -0.44017248 | AX10: NA | AY10: NA | AZ10: NA | BA10: NA | BB10: NA | BC10: NA | BD10: NA | BE10: NA | BF10: NA | BG10: NA | BH10: NA | BI10: NA | BJ10: NA | BK10: NA | BL10: NA | BM10: NA | BN10: NA | BO10: NA | BP10: NA | BQ10: NA | BR10: NA | BS10: NA | BT10: NA | BU10: NA | BV10: NA | BW10: NA | BX10: NA | BY10: NA | BZ10: NA | CA10: NA | CB10: NA | CC10: NA | CD10: NA | CE10: NA | CF10: NA | CG10: NA | CH10: NA | CI10: NA
A11: Nicotine | B11: =VLOOKUP(A11,MOA!$C$2333:$D$3565,2,FALSE) -> Acetylcholine receptor agonist | C11: 0 | D11: 4 | E11: 0 | F11: NA | G11: NA | H11: NA | I11: NA | J11: NA | K11: NA | L11: NA | M11: NA | N11: NA | O11: NA | P11: NA | Q11: NA | R11: NA | S11: -0.45086285 | T11: NA | U11: NA | V11: NA | W11: NA | X11: NA | Y11: NA | Z11: NA | AA11: NA | AB11: NA | AC11: -0.50740862 | AD11: NA | AE11: NA | AF11: NA | AG11: NA | AH11: NA | AI11: NA | AJ11: NA | AK11: NA | AL11: NA | AM11: NA | AN11: NA | AO11: NA | AP11: NA | AQ11: NA | AR11: NA | AS11: NA | AT11: NA | AU11: NA | AV11: NA | AW11: -0.4548878 | AX11: NA | AY11: NA | AZ11: NA | BA11: NA | BB11: NA | BC11: NA | BD11: NA | BE11: NA | BF11: NA | BG11: NA | BH11: -0.41059276 | BI11: NA | BJ11: NA | BK11: NA | BL11: NA | BM11: NA | BN11: NA | BO11: NA | BP11: NA | BQ11: NA | BR11: NA | BS11: NA | BT11: NA | BU11: NA | BV11: NA | BW11: NA | BX11: NA | BY11: NA | BZ11: NA | CA11: NA | CB11: NA | CC11: NA | CD11: NA | CE11: NA | CF11: NA | CG11: NA | CH11: NA | CI11: NA
A12: Diphenidol | B12: =VLOOKUP(A12,MOA!$C$2333:$D$3565,2,FALSE) -> Acetylcholine receptor agonist | C12: 0 | D12: 4 | E12: 0 | F12: NA | G12: NA | H12: NA | I12: -0.46531787 | J12: NA | K12: NA | L12: NA | M12: NA | N12: NA | O12: NA | P12: NA | Q12: NA | R12: NA | S12: -0.49599391 | T12: NA | U12: NA | V12: NA | W12: NA | X12: NA | Y12: NA | Z12: NA | AA12: NA | AB12: NA | AC12: -0.42458772 | AD12: NA | AE12: NA | AF12: NA | AG12: NA | AH12: NA | AI12: NA | AJ12: NA | AK12: NA | AL12: NA | AM12: NA | AN12: NA | AO12: NA | AP12: NA | AQ12: NA | AR12: NA | AS12: NA | AT12: NA | AU12: NA | AV12: NA | AW12: NA | AX12: NA | AY12: NA | AZ12: NA | BA12: NA | BB12: NA | BC12: NA | BD12: NA | BE12: NA | BF12: NA | BG12: NA | BH12: -0.38186844 | BI12: NA | BJ12: NA | BK12: NA | BL12: NA | BM12: NA | BN12: NA | BO12: NA | BP12: NA | BQ12: NA | BR12: NA | BS12: NA | BT12: NA | BU12: NA | BV12: NA | BW12: NA | BX12: NA | BY12: NA | BZ12: NA | CA12: NA | CB12: NA | CC12: NA | CD12: NA | CE12: NA | CF12: NA | CG12: NA | CH12: NA | CI12: NA
A13: Pilocarpine | B13: =VLOOKUP(A13,MOA!$C$2333:$D$3565,2,FALSE) -> Acetylcholine receptor agonist | C13: 3 | D13: 2 | E13: 1.5 | F13: NA | G13: NA | H13: NA | I13: 0.47175387 | J13: NA | K13: NA | L13: NA | M13: NA | N13: NA | O13: NA | P13: NA | Q13: NA | R13: 0.51382658 | S13: NA | T13: NA | U13: NA | V13: NA | W13: NA | X13: NA | Y13: NA | Z13: NA | AA13: NA | AB13: -0.45305057 | AC13: 0.41674994 | AD13: NA | AE13: NA | AF13: NA | AG13: NA | AH13: NA | AI13: NA | AJ13: NA | AK13: NA | AL13: NA | AM13: NA | AN13: NA | AO13: NA | AP13: NA | AQ13: NA | AR13: NA | AS13: NA | AT13: NA | AU13: NA | AV13: NA | AW13: NA | AX13: NA | AY13: NA | AZ13: NA | BA13: NA | BB13: NA | BC13: NA | BD13: NA | BE13: NA | BF13: NA | BG13: NA | BH13: -0.34394645 | BI13: NA | BJ13: NA | BK13: NA | BL13: NA | BM13: NA | BN13: NA | BO13: NA | BP13: NA | BQ13: NA | BR13: NA | BS13: NA | BT13: NA | BU13: NA | BV13: NA | BW13: NA | BX13: NA | BY13: NA | BZ13: NA | CA13: NA | CB13: NA | CC13: NA | CD13: NA | CE13: NA | CF13: NA | CG13: NA | CH13: NA | CI13: NA
A14: N-Methyltropan-3-yl 2-(4-bromophenyl)propionate | B14: =VLOOKUP(A14,MOA!$C$2333:$D$3565,2,FALSE) -> Acetylcholine receptor agonist | C14: 2 | D14: 2 | E14: 1 | F14: NA | G14: NA | H14: NA | I14: NA | J14: NA | K14: NA | L14: NA | M14: 0.40223161 | N14: NA | O14: NA | P14: NA | Q14: NA | R14: NA | S14: 0.36650069 | T14: NA | U14: NA | V14: NA | W14: NA | X14: NA | Y14: NA | Z14: NA | AA14: NA | AB14: -0.40653133 | AC14: NA | AD14: NA | AE14: NA | AF14: NA | AG14: NA | AH14: NA | AI14: NA | AJ14: -0.35685873 | AK14: NA | AL14: NA | AM14: NA | AN14: NA | AO14: NA | AP14: NA | AQ14: NA | AR14: NA | AS14: NA | AT14: NA | AU14: NA | AV14: NA | AW14: NA | AX14: NA | AY14: NA | AZ14: NA | BA14: NA | BB14: NA | BC14: NA | BD14: NA | BE14: NA | BF14: NA | BG14: NA | BH14: NA | BI14: NA | BJ14: NA | BK14: NA | BL14: NA | BM14: NA | BN14: NA | BO14: NA | BP14: NA | BQ14: NA | BR14: NA | BS14: NA | BT14: NA | BU14: NA | BV14: NA | BW14: NA | BX14: NA | BY14: NA | BZ14: NA | CA14: NA | CB14: NA | CC14: NA | CD14: NA | CE14: NA | CF14: NA | CG14: NA | CH14: NA | CI14: NA
A15: N-Desmethylclozapine | B15: =VLOOKUP(A15,MOA!$C$2333:$D$3565,2,FALSE) -> Acetylcholine receptor agonist | C15: 0 | D15: 3 | E15: 0 | F15: NA | G15: NA | H15: NA | I15: NA | J15: NA | K15: NA | L15: -0.37509716 | M15: NA | N15: -0.44269037 | O15: NA | P15: NA | Q15: NA | R15: NA | S15: NA | T15: NA | U15: NA | V15: NA | W15: NA | X15: NA | Y15: NA | Z15: NA | AA15: NA | AB15: NA | AC15: NA | AD15: NA | AE15: NA | AF15: NA | AG15: NA | AH15: NA | AI15: NA | AJ15: -0.39805814 | AK15: NA | AL15: NA | AM15: NA | AN15: NA | AO15: NA | AP15: NA | AQ15: NA | AR15: NA | AS15: NA | AT15: NA | AU15: NA | AV15: NA | AW15: NA | AX15: NA | AY15: NA | AZ15: NA | BA15: NA | BB15: NA | BC15: NA | BD15: NA | BE15: NA | BF15: NA | BG15: NA | BH15: NA | BI15: NA | BJ15: NA | BK15: NA | BL15: NA | BM15: NA | BN15: NA | BO15: NA | BP15: NA | BQ15: NA | BR15: NA | BS15: NA | BT15: NA | BU15: NA | BV15: NA | BW15: NA | BX15: NA | BY15: NA | BZ15: NA | CA15: NA | CB15: NA | CC15: NA | CD15: NA | CE15: NA | CF15: NA | CG15: NA | CH15: NA | CI15: NA
A16: Piperidolate | B16: =VLOOKUP(A16,MOA!$C$2333:$D$3565,2,FALSE) -> Acetylcholine receptor antagonist | C16: 1 | D16: 1 | E16: 1 | F16: NA | G16: NA | H16: NA | I16: NA | J16: NA | K16: NA | L16: NA | M16: NA | N16: NA | O16: NA | P16: NA | Q16: NA | R16: NA | S16: NA | T16: NA | U16: NA | V16: NA | W16: NA | X16: NA | Y16: NA | Z16: NA | AA16: NA | AB16: -0.5646538 | AC16: 0.46705876 | AD16: NA | AE16: NA | AF16: NA | AG16: NA | AH16: NA | AI16: NA | AJ16: NA | AK16: NA | AL16: NA | AM16: NA | AN16: NA | AO16: NA | AP16: NA | AQ16: NA | AR16: NA | AS16: NA | AT16: NA | AU16: NA | AV16: NA | AW16: NA | AX16: NA | AY16: NA | AZ16: NA | BA16: NA | BB16: NA | BC16: NA | BD16: NA | BE16: NA | BF16: NA | BG16: NA | BH16: NA | BI16: NA | BJ16: NA | BK16: NA | BL16: NA | BM16: NA | BN16: NA | BO16: NA | BP16: NA | BQ16: NA | BR16: NA | BS16: NA | BT16: NA | BU16: NA | BV16: NA | BW16: NA | BX16: NA | BY16: NA | BZ16: NA | CA16: NA | CB16: NA | CC16: NA | CD16: NA | CE16: NA | CF16: NA | CG16: NA | CH16: NA | CI16: NA
A17: Tubocurarine | B17: =VLOOKUP(A17,MOA!$C$2333:$D$3565,2,FALSE) -> Acetylcholine receptor antagonist | C17: 0 | D17: 2 | E17: 0 | F17: NA | G17: NA | H17: NA | I17: NA | J17: NA | K17: NA | L17: NA | M17: NA | N17: -0.40981423 | O17: NA | P17: NA | Q17: NA | R17: NA | S17: NA | T17: NA | U17: NA | V17: NA | W17: NA | X17: NA | Y17: NA | Z17: NA | AA17: NA | AB17: NA | AC17: -0.50773161 | AD17: NA | AE17: NA | AF17: NA | AG17: NA | AH17: NA | AI17: NA | AJ17: NA | AK17: NA | AL17: NA | AM17: NA | AN17: NA | AO17: NA | AP17: NA | AQ17: NA | AR17: NA | AS17: NA | AT17: NA | AU17: NA | AV17: NA | AW17: NA | AX17: NA | AY17: NA | AZ17: NA | BA17: NA | BB17: NA | BC17: NA | BD17: NA | BE17: NA | BF17: NA | BG17: NA | BH17: NA | BI17: NA | BJ17: NA | BK17: NA | BL17: NA | BM17: NA | BN17: NA | BO17: NA | BP17: NA | BQ17: NA | BR17: NA | BS17: NA | BT17: NA | BU17: NA | BV17: NA | BW17: NA | BX17: NA | BY17: NA | BZ17: NA | CA17: NA | CB17: NA | CC17: NA | CD17: NA | CE17: NA | CF17: NA | CG17: NA | CH17: NA | CI17: NA
